{
	"schema_version": "1.6.0",
	"id": "UBUNTU-CVE-2015-5159",
	"modified": "2025-01-13T10:21:10Z",
	"published": "2018-10-30T18:29:00Z",
	"related": [
		"CVE-2015-5159"
	],
	"details": "python-kdcproxy before 0.3.2 allows remote attackers to cause a denial of service via a large POST request.",
	"severity": [
		{
			"type": "CVSS_V3",
			"score": "CVSS:3.0/AV:N/AC:L/PR:N/UI:N/S:U/C:N/I:N/A:H"
		}
	],
	"affected": [
		{
			"package": {
				"ecosystem": "Ubuntu:16.04:LTS",
				"name": "python-kdcproxy",
				"purl": "pkg:deb/ubuntu/python-kdcproxy@0.3.2-1?arch=source&distro=xenial"
			},
			"ranges": [
				{
					"type": "ECOSYSTEM",
					"events": [
						{
							"introduced": "0"
						},
						{
							"fixed": "0.3.2-1"
						}
					]
				}
			],
			"ecosystem_specific": {
				"availability": "No subscription required",
				"binaries": [
					{
						"binary_name": "python-kdcproxy",
						"binary_version": "0.3.2-1"
					},
					{
						"binary_name": "python3-kdcproxy",
						"binary_version": "0.3.2-1"
					}
				],
				"ubuntu_priority": "medium"
			},
			"database_specific": {
				"source": "https://github.com/canonical/ubuntu-security-notices/blob/main/osv/cve/2015/UBUNTU-CVE-2015-5159.json"
			}
		}
	],
	"references": [
		{
			"type": "REPORT",
			"url": "https://ubuntu.com/security/CVE-2015-5159"
		},
		{
			"type": "REPORT",
			"url": "https://bugzilla.redhat.com/show_bug.cgi?id=1245200"
		},
		{
			"type": "REPORT",
			"url": "https://github.com/latchset/kdcproxy/commit/f274aa6787cb8b3ec1cc12c440a56665b7231882"
		},
		{
			"type": "REPORT",
			"url": "https://www.cve.org/CVERecord?id=CVE-2015-5159"
		}
	]
}
