{
	"schema_version": "1.6.0",
	"id": "USN-4479-1",
	"modified": "2020-09-01T10:56:50.210734Z",
	"published": "2020-09-01T10:56:50.210734Z",
	"related": [
		"CVE-2020-24583",
		"CVE-2020-24584",
		"UBUNTU-CVE-2020-24583",
		"UBUNTU-CVE-2020-24584"
	],
	"summary": "python-django vulnerabilities",
	"details": "It was discovered that Django, when used with Python 3.7 or higher,\nincorrectly handled directory permissions. A local attacker could possibly\nuse this issue to obtain sensitive information, or escalate permissions.\n",
	"affected": [
		{
			"package": {
				"ecosystem": "Ubuntu:20.04:LTS",
				"name": "python-django",
				"purl": "pkg:deb/ubuntu/python-django@2:2.2.12-1ubuntu0.2?arch=source&distro=focal"
			},
			"ranges": [
				{
					"type": "ECOSYSTEM",
					"events": [
						{
							"introduced": "0"
						},
						{
							"fixed": "2:2.2.12-1ubuntu0.2"
						}
					]
				}
			],
			"versions": [
				"1:1.11.22-1ubuntu1",
				"2:2.2.6-1ubuntu1",
				"2:2.2.9-2ubuntu1",
				"2:2.2.10-1",
				"2:2.2.10-1ubuntu1",
				"2:2.2.11-1",
				"2:2.2.12-1",
				"2:2.2.12-1ubuntu0.1"
			],
			"ecosystem_specific": {
				"availability": "No subscription required",
				"binaries": [
					{
						"binary_name": "python-django-doc",
						"binary_version": "2:2.2.12-1ubuntu0.2"
					},
					{
						"binary_name": "python3-django",
						"binary_version": "2:2.2.12-1ubuntu0.2"
					}
				]
			},
			"database_specific": {
				"source": "https://github.com/canonical/ubuntu-security-notices/blob/main/osv/usn/USN-4479-1.json"
			}
		}
	],
	"references": [
		{
			"type": "ADVISORY",
			"url": "https://ubuntu.com/security/notices/USN-4479-1"
		},
		{
			"type": "REPORT",
			"url": "https://ubuntu.com/security/CVE-2020-24583"
		},
		{
			"type": "REPORT",
			"url": "https://ubuntu.com/security/CVE-2020-24584"
		}
	]
}
